Workbook

Sheet DASHBOARD
B2: FOOTBALL SCOUTING | PLAYER COMPARISON DASHBOARD
B4: PLAYER 1 | F4: VS | H4: PLAYER 2
B5: Bruno Fernandes | H5: Bernardo Silva
B6: Club | C6: =IFERROR(XLOOKUP($B$5,DATA!$A:$A,DATA!$C:$C,"--"),"--") | I6: =IFERROR(XLOOKUP($H$5,DATA!$A:$A,DATA!$C:$C,"--"),"--")
B7: Position | C7: =IFERROR(XLOOKUP($B$5,DATA!$A:$A,DATA!$D:$D,"--"),"--") | I7: =IFERROR(XLOOKUP($H$5,DATA!$A:$A,DATA!$D:$D,"--"),"--")
B8: Nat. | C8: =IFERROR(XLOOKUP($B$5,DATA!$A:$A,DATA!$E:$E,"--"),"--") | I8: =IFERROR(XLOOKUP($H$5,DATA!$A:$A,DATA!$E:$E,"--"),"--")
B9: Age | C9: =IFERROR(XLOOKUP($B$5,DATA!$A:$A,DATA!$B:$B,"--"),"--") | I9: =IFERROR(XLOOKUP($H$5,DATA!$A:$A,DATA!$B:$B,"--"),"--")
B10: Rating | C10: =IFERROR(ROUND(XLOOKUP($B$5,DATA!$A:$A,DATA!$F:$F,0),1),"--") | I10: =IFERROR(ROUND(XLOOKUP($H$5,DATA!$A:$A,DATA!$F:$F,0),1),"--")
B12: PERCENTILE SCORES ( 0 = lowest / 100 = highest in database )
B14: Scoring | D14: Creating | F14: Defending | H14: Possession | J14: Dribbling
B15: =IFERROR(ROUND(XLOOKUP($B$5,DATA!$A:$A,DATA!$V:$V,0),1),"--") | D15: =IFERROR(ROUND(XLOOKUP($B$5,DATA!$A:$A,DATA!$Y:$Y,0),1),"--") | F15: =IFERROR(ROUND(XLOOKUP($B$5,DATA!$A:$A,DATA!$Z:$Z,0),1),"--") | H15: =IFERROR(ROUND(XLOOKUP($B$5,DATA!$A:$A,DATA!$AB:$AB,0),1),"--") | J15: =IFERROR(ROUND(XLOOKUP($B$5,DATA!$A:$A,DATA!$AC:$AC,0),1),"--")
B16: =IFERROR(ROUND(XLOOKUP($H$5,DATA!$A:$A,DATA!$V:$V,0),1),"--") | D16: =IFERROR(ROUND(XLOOKUP($H$5,DATA!$A:$A,DATA!$Y:$Y,0),1),"--") | F16: =IFERROR(ROUND(XLOOKUP($H$5,DATA!$A:$A,DATA!$Z:$Z,0),1),"--") | H16: =IFERROR(ROUND(XLOOKUP($H$5,DATA!$A:$A,DATA!$AB:$AB,0),1),"--") | J16: =IFERROR(ROUND(XLOOKUP($H$5,DATA!$A:$A,DATA!$AC:$AC,0),1),"--")
B17: =IFERROR(ROUND(XLOOKUP($B$5,DATA!$A:$A,DATA!$V:$V,0)-XLOOKUP($H$5,DATA!$A:$A,DATA!$V:$V,0),1),"--") | D17: =IFERROR(ROUND(XLOOKUP($B$5,DATA!$A:$A,DATA!$Y:$Y,0)-XLOOKUP($H$5,DATA!$A:$A,DATA!$Y:$Y,0),1),"--") | F17: =IFERROR(ROUND(XLOOKUP($B$5,DATA!$A:$A,DATA!$Z:$Z,0)-XLOOKUP($H$5,DATA!$A:$A,DATA!$Z:$Z,0),1),"--") | H17: =IFERROR(ROUND(XLOOKUP($B$5,DATA!$A:$A,DATA!$AB:$AB,0)-XLOOKUP($H$5,DATA!$A:$A,DATA!$AB:$AB,0),1),"--") | J17: =IFERROR(ROUND(XLOOKUP($B$5,DATA!$A:$A,DATA!$AC:$AC,0)-XLOOKUP($H$5,DATA!$A:$A,DATA!$AC:$AC,0),1),"--") | L17: P1 - P2
B18: RADAR | Percentile scores (0 - 100) | H18: METRICS | Values per 90 min
B50: Player 1 | E50: Radar = percentile vs all players in DB | H50: Player 2
B51: Football Successor 2026 | Source: mart.player_profile_merged_v1 | Atualizar: Dados -> Atualizar Tudo

Sheet DATA
A1: INSTRUCOES | Exporta o CSV do Supabase com a query abaixo. No Excel: Dados -> Obter Dados -> Do Ficheiro -> Do CSV -> carregar nesta sheet substituindo os dados existentes (linha 10 em diante).
A2: SELECT
A3: name, age, club, positions, nationality, rating_merged,
A4: goals_p90_merged, assists_p90_merged, xg_per_90_merged, shots_p90_merged,
A5: key_passes_p90_merged, passes_p90_merged, accurate_crosses_p90_merged,
A6: interceptions_p90_merged, tackles_p90_merged, blocks_p90_merged,
A7: dribbles_won_p90_merged, aerial_won_p90_merged, pass_success_pct_merged,
A8: dispossessed_p90_merged, turnovers_p90_merged,
A9: goals_p90_pct_merged, assists_p90_pct_merged, xg_per_90_pct_merged,
A10: key_passes_p90_pct_merged, tackles_p90_pct_merged, interceptions_p90_pct_merged,
A11: pass_success_pct_pct_merged, dribbles_won_p90_pct_merged, aerial_won_p90_pct_merged
A12: FROM mart.player_profile_merged_v1
... A14: ORDER BY name ASC;
A17: name | B17: age | C17: club | D17: positions | E17: nationality | F17: rating_merged | G17: goals_p90_merged | H17: assists_p90_merged | I17: xg_per_90_merged | J17: shots_p90_merged | K17: key_passes_p90_merged | L17: passes_p90_merged | M17: accurate_crosses_p90_merged | N17: interceptions_p90_merged | O17: tackles_p90_merged | P17: blocks_p90_merged | Q17: dribbles_won_p90_merged | R17: aerial_won_p90_merged | S17: pass_success_pct_merged | T17: dispossessed_p90_merged | U17: turnovers_p90_merged | V17: goals_p90_pct_merged | W17: assists_p90_pct_merged | X17: xg_per_90_pct_merged | Y17: key_passes_p90_pct_merged | Z17: tackles_p90_pct_merged | AA17: interceptions_p90_pct_merged | AB17: pass_success_pct_pct_merged | AC17: dribbles_won_p90_pct_merged | AD17: aerial_won_p90_pct_merged
A18: -- DADOS DO SUPABASE ABAIXO --
A19: Aaron Appindangoyé | B19: 34 | C19: Sivasspor | D19: D(C) | E19: ga | F19: 6.5543918 | G19: 0.023622047 | H19: 0.023622047 | I19: 0.033288543 | J19: 0.39685039 | K19: 0.15826772 | L19: 39.364961 | M19: 0 | N19: 1.0523622 | O19: 0.5007874 | P19: 0.94251969 | Q19: 0.087401575 | R19: 1.7751969 | S19: 81.716333 | T19: 0.1511811 | U19: 0.28937008 | V19: 22.97 | W19: 21.33 | X19: 21.68 | Y19: 5.67 | Z19: 3.87 | AA19: 57.65 | AB19: 53.3 | AC19: 4.53 | AD19: 71.36
A20: Aaron Cresswell | B20: 36 | C20: Stoke | D20: D(CL),M(L) | E20: gb-eng | F20: 6.674155 | G20: 0.022447689 | H20: 0.095402678 | I20: 0.024805819 | J20: 0.53313261 | K20: 1.1977445 | L20: 50.752621 | M20: 1.3067762 | N20: 1.0494295 | O20: 0.95322507 | P20: 0.40004988 | Q20: 0.14911679 | R20: 1.1095572 | S20: 82.777341 | T20: 0.14270316 | U20: 0.49545256 | V20: 15.82 | W20: 59.87 | X20: 14.98 | Y20: 67.68 | Z20: 21.5 | AA20: 62.07 | AB20: 65.4 | AC20: 11.15 | AD20: 44.76
A21: Aaron Donnelly | B21: 22 | C21: Dundee FC | D21: D(C) | E21: gb-nir | F21: 6.6717647 | G21: 0 | H21: 0.13274336 | I21: 0.036338496 | J21: 0.79646018 | K21: 0.59734513 | L21: 41.150442 | M21: 0.26548673 | N21: 0.86283186 | O21: 0.7300885 | P21: 0.79646018 | Q21: 0 | R21: 3.5840708 | S21: 61.612903 | T21: 0 | U21: 0.26548673 | V21: 0 | W21: 72.29 | X21: 8.43 | Y21: 30.12 | Z21: 12.05 | AA21: 63.86 | AB21: 6.02 | AC21: 0 | AD21: 81.93
A22: Aaron Hickey | B22: 23 | C22: Brentford | D22: D(LR),M(LR) | E22: gb-sct | F22: 6.5859748 | G22: 0.088118413 | H22: 0.038357427 | I22: 0.0076631918 | J22: 0.59816852 | K22: 0.12440247 | L22: 15.073432 | M22: 0.082934977 | N22: 0.35247365 | O22: 0.78788228 | P22: 0.14513621 | Q22: 0.35247365 | R22: 0.6074987 | S22: 83.795749 | T22: 0.26953867 | U22: 0.33173991 | V22: 35.48 | W22: 33.55 | X22: 6.15 | Y22: 7.03 | Z22: 24.62 | AA22: 18.81 | AB22: 64.02 | AC22: 23.74 | AD22: 25.1
A23: Aarón Martín | B23: 28 | C23: Genoa | D23: D(L),M(L) | E23: es | F23: 6.7624897 | G23: 0.051703731 | H23: 0.1688158 | I23: 0.027211425 | J23: 0.50769327 | K23: 2.002118 | L23: 32.50732 | M23: 2.2525385 | N23: 0.59428144 | O23: 1.8906123 | P23: 0.26537096 | Q23: 0.52451255 | R23: 0.44041612 | S23: 79.329521 | T23: 0.53510247 | U23: 0.76683486 | V23: 22.94 | W23: 73.91 | X23: 12.86 | Y23: 89.91 | Z23: 69.77 | AA23: 36.79 | AB23: 37.69 | AC23: 45.49 | AD23: 14.75
A24: Aaron Opoku | B24: 26 | C24: Kayserispor | D24: D(R),M(LR) | E24: gh | F24: 6.3536842 | G24: 0 | H24: 0.1453958 | I24: 0.064359451 | J24: 0.9450727 | K24: 1.5266559 | L24: 23.045234 | M24: 0.8723748 | N24: 0.5088853 | O24: 1.0177706 | P24: 0.0726979 | Q24: 1.2358643 | R24: 1.0177706 | S24: 76.656151 | T24: 0.9450727 | U24: 1.453958 | V24: 0 | W24: 76.6 | X24: 38.83 | Y24: 82.98 | Z24: 25.53 | AA24: 28.72 | AB24: 23.4 | AC24: 84.04 | AD24: 49.47
A25: Aaron Ramsey | B25: 23 | C25: Norwich | D25: AM(CL) | E25: gb-eng | F25: 6.6338889 | G25: 0.25911708 | H25: 0.25911708 | I25: null | J25: 1.4683301 | K25: 1.8138196 | L25: 37.744722 | M25: 0.086372361 | N25: 0.25911708 | O25: 1.2092131 | P25: 0.086372361 | Q25: 0.69097889 | R25: 0.51823417 | S25: 80.778032 | T25: 1.0364683 | U25: 2.159309 | V25: 82.11 | W25: 97.15 | X25: 7.32 | Y25: 92.68 | Z25: 29.67 | AA25: 9.76 | AB25: 71.54 | AC25: 54.07 | AD25: 12.6
A26: Aaron Wan-Bissaka | B26: 28 | C26: West Ham | D26: D(LR),M(R) | E26: cd | F26: 6.9246483 | G26: 0.021340251 | H26: 0.096031132 | I26: 0.02354652 | J26: 0.29123167 | K26: 0.8448229 | L26: 40.866582 | M26: 0.46760257 | N26: 1.8515806 | O26: 1.9520054 | P26: 0.43747516 | Q26: 1.2935958 | R26: 0.86616315 | S26: 81.18122 | T26: 0.58622926 | U26: 1.0249597 | V26: 15.94 | W26: 52.88 | X26: 37.91 | Y26: 50.92 | Z26: 61.85 | AA26: 96.38 | AB26: 41.63 | AC26: 76.31 | AD26: 38.24
A27: Aaron Zehnter | B27: 21 | C27: Wolfsburg | D27: D(L),M(L) | E27: de | F27: 6.535 | G27: 0.14863749 | H27: 0 | I27: 0.057344344 | J27: 0.59454996 | K27: 1.1147812 | L27: 37.382329 | M27: 0.89182494 | N27: 1.1890999 | O27: 0.89182494 | P27: 0.44591247 | Q27: 0.29727498 | R27: 0.59454996 | S27: 78.926441 | T27: 0 | U27: 0.59454996 | V27: 60.89 | W27: 0 | X27: 29.21 | Y27: 60.89 | Z27: 13.86 | AA27: 74.75 | AB27: 38.12 | AC27: 30.69 | AD27: 23.76
A28: Abakar Sylla | B28: 23 | C28: Strasbourg | D28: D(C) | E28: ci | F28: 6.5376508 | G28: 0.072106825 | H28: 0 | I28: 0.05851776 | J28: 0.55148368 | K28: 0.1962908 | L28: 63.112166 | M28: 0 | N28: 1.3700297 | O28: 2.451632 | P28: 0.72240356 | Q28: 0.52744807 | R28: 1.8400593 | S28: 87.848434 | T28: 0.37789318 | U28: 0.73175074 | V28: 41.33 | W28: 0 | X28: 37.02 | Y28: 8.81 | Z28: 78.09 | AA28: 74.85 | AB28: 86.65 | AC28: 33.93 | AD28: 76.91
A29: Abdallah Sima | B29: 24 | C29: Brest | D29: AM(LR),FW | E29: sn | F29: 6.7116313 | G29: 0.45978639 | H29: 0.10191739 | I29: 0.44652543 | J29: 2.8872732 | K29: 0.97400592 | L29: 22.135761 | M29: 0.15750869 | N29: 0.1667739 | O29: 1.2554369 | P29: 0.062540214 | Q29: 1.0898211 | R29: 3.1235362 | S29: 72.188452 | T29: 1.6422597 | U29: 3.6574443 | V29: 90.62 | W29: 55.01 | X29: 89.76 | Y29: 54.09 | Z29: 31.05 | AA29: 9.01 | AB29: 22.17 | AC29: 60.55 | AD29: 89.59
A30: Abde Ezzalzouli | B30: 24 | C30: Real Betis | D30: AM(L) | E30: ma | F30: 6.8327485 | G30: 0.21410595 | H30: 0.16001603 | I30: 0.37450996 | J30: 2.8329598 | K30: 1.0671491 | L30: 30.523621 | M30: 0.35834575 | N30: 0.42257754 | O30: 1.8649755 | P30: 0.057470545 | Q30: 2.3303742 | R30: 1.0186936 | S30: 76.506853 | T30: 2.1207758 | U30: 3.2949779 | V30: 71.53 | W30: 72.19 | X30: 87.18 | Y30: 64.16 | Z30: 63.91 | AA30: 22.7 | AB30: 20.82 | AC30: 94.42 | AD30: 45.93
A31: Abdel Abqar | B31: 26 | C31: Getafe | D31: D(C) | E31: ma | F31: 6.5578236 | G31: 0 | H31: 0.036007785 | I31: 0.035612576 | J31: 0.47102076 | K31: 0.23161765 | L31: 31.132137 | M31: 0.033088235 | N31: 1.231077 | O31: 1.5979671 | P31: 0.72988754 | Q31: 0.12943339 | R31: 1.5376298 | S31: 74.519649 | T31: 0.082720588 | U31: 0.65787197 | V31: 0 | W31: 26.94 | X31: 22.12 | Y31: 11.68 | Z31: 47.33 | AA31: 81.13 | AB31: 16.72 | AC31: 9.22 | AD31: 67.87
A32: Abdelhamid Sabiri | B32: 29 | C32: Sampdoria | D32: AM(CL),FW | E32: ma | F32: 6.4427778 | G32: 0.16806723 | H32: 0 | I32: 0.27890756 | J32: 2.7731092 | K32: 1.1764706 | L32: 33.781513 | M32: 0.84033613 | N32: 0.16806723 | O32: 1.512605 | P32: 0.33613445 | Q32: 1.1764706 | R32: 2.5210084 | S32: 74.129353 | T32: 2.3529412 | U32: 2.8571429 | V32: 69.73 | W32: 0 | X32: 83.24 | Y32: 68.11 | Z32: 48.65 | AA32: 7.03 | AB32: 17.3 | AC32: 75.68 | AD32: 85.41
A33: Abdelkahar Kadri | B33: 25 | C33: Gent | D33: AM(CLR),FW | E33: dz | F33: 6.9378883 | G33: 0.11128166 | H33: 0.21949348 | I33: 0.099500384 | J33: 1.5464313 | K33: 1.6469685 | L33: 45.594781 | M33: 0.85878741 | N33: 0.96239447 | O33: 2.2547966 | P33: 0.11358404 | Q33: 2.1603991 | R33: 0.47122026 | S33: 83.428985 | T33: 1.7198772 | U33: 2.1174213 | V33: 49.82 | W33: 79.2 | X33: 42.76 | Y33: 83.83 | Z33: 70.92 | AA33: 48.77 | AB33: 71.98 | AC33: 90.65 | AD33: 17.53
A34: Abdón Prats | B34: 33 | C34: Mallorca | D34: FW | E34: es | F34: 6.3979412 | G34: 0.42891183 | H34: 0.071485306 | I34: 0.27798491 | J34: 2.3590151 | K34: 1.0007943 | L34: 16.513106 | M34: 0.071485306 | N34: 0.14297061 | O34: 0.42891183 | P34: 0.21445592 | Q34: 0.57188245 | R34: 2.9308975 | S34: 56.709957 | T34: 0.71485306 | U34: 2.9308975 | V34: 92.41 | W34: 47.77 | X34: 81.7 | Y34: 61.16 | Z34: 4.46 | AA34: 5.8 | AB34: 0.45 | AC34: 44.2 | AD34: 92.41
A35: Abdou Harroui | B35: 28 | C35: Frosinone | D35: M(CLR) | E35: nl | F35: 6.6394444 | G35: 0.26264591 | H35: 0.26264591 | I35: 0.3287714 | J35: 2.8891051 | K35: 1.4007782 | L35: 31.605058 | M35: 0.35019455 | N35: 0.43774319 | O35: 2.0136187 | P35: 0.26264591 | Q35: 1.6634241 | R35: 1.0505837 | S35: 81.717452 | T35: 0.61284047 | U35: 2.4513619 | V35: 80.82 | W35: 93.88 | X35: 88.16 | Y35: 77.14 | Z35: 81.63 | AA35: 31.02 | AB35: 47.76 | AC35: 90.61 | AD35: 45.31
A36: Abdoul Ouattara | B36: 20 | C36: Strasbourg | D36: M(R) | E36: fr | F36: 6.3957895 | G36: 0.15915119 | H36: 0 | I36: 0.12646437 | J36: 1.193634 | K36: 0.30238727 | L36: 38.629973 | M36: 0.22679045 | N36: 0.68037135 | O36: 1.3607427 | P36: 0 | Q36: 0.37798408 | R36: 0 | S36: 89.194915 | T36: 0.37798408 | U36: 1.4363395 | V36: 68.75 | W36: 0 | X36: 64.06 | Y36: 17.19 | Z36: 36.98 | AA36: 34.38 | AB36: 80.73 | AC36: 33.33 | AD36: 0
A37: Abdoulaye Bamba | B37: 35 | C37: Angers | D37: D(CLR),M(R) | E37: ci | F37: 6.3052238 | G37: 0 | H37: 0 | I37: 0.0093134295 | J37: 0.03375654 | K37: 0.31731148 | L37: 37.525458 | M37: 0.22110534 | N37: 1.1578493 | O37: 1.3738912 | P37: 0.3561315 | Q37: 0.18228532 | R37: 0.85910395 | S37: 89.323607 | T37: 0.2497984 | U37: 0.35950715 | V37: 0 | W37: 0 | X37: 47.83 | Y37: 18.25 | Z37: 31.46 | AA37: 69.48 | AB37: 86.22 | AC37: 8.92 | AD37: 44.7
... A64: Adam Masina | B64: 32 | C64: Torino | D64: D(CL),M(L) | E64: ma | F64: 6.6021252 | G64: 0.025411167 | H64: 0.06861015 | I64: 0.042253434 | J64: 0.40022588 | K64: 0.29095786 | L64: 52.242818 | M64: 0.2439472 | N64: 1.2438766 | O64: 1.6326675 | P64: 0.61749135 | Q64: 0.33415684 | R64: 2.7189948 | S64: 82.510641 | T64: 0.3506741 | U64: 0.56921014 | V64: 20.25 | W64: 44.35 | X64: 25.8 | Y64: 13.22 | Z64: 54.44 | AA64: 86.25 | AB64: 55.21 | AC64: 28.14 | AD64: 87.06
A65: Adam Montgomery | B65: 23 | C65: St. Johnstone | D65: D(L),M(L) | E65: gb-sct | F65: 6.5908696 | G65: 0 | H65: 0.048465267 | I65: null | J65: 0.2907916 | K65: 0.53311793 | L65: 27.431341 | M65: 0.1453958 | N65: 0.96930533 | O65: 1.5993538 | P65: 0.2907916 | Q65: 1.1631664 | R65: 0.726979 | S65: 72.438163 | T65: 0.96930533 | U65: 1.1631664 | V65: 0 | W65: 41.67 | X65: 0 | Y65: 27.78 | Z65: 48.61 | AA65: 58.33 | AB65: 40.28 | AC65: 90.28 | AD65: 15.28
A66: Adam Obert | B66: 23 | C66: Cagliari | D66: D(CL),M(L) | E66: sk | F66: 6.548235 | G66: 0.022552069 | H66: 0.07561576 | I66: 0.05425803 | J66: 0.36481288 | K66: 0.66807187 | L66: 40.685259 | M66: 0.41893784 | N66: 1.8001857 | O66: 2.1610188 | P66: 0.64445853 | Q66: 0.42318294 | R66: 1.4340463 | S66: 79.986984 | T66: 0.37330307 | U66: 1.1865041 | V66: 13.95 | W66: 50.57 | X66: 27.77 | Y66: 36.22 | Z66: 81.37 | AA66: 97.77 | AB66: 34.37 | AC66: 43.57 | AD66: 56.72
A67: Adam Randell | B67: 25 | C67: Bristol City | D67: DMC | E67: gb-eng | F67: 6.6830252 | G67: 0.058256617 | H67: 0.058256617 | I67: 0.047467297 | J67: 0.85325348 | K67: 1.0917441 | L67: 40.779968 | M67: 0.5532277 | N67: 1.1704284 | O67: 1.5587218 | P67: 0.65133083 | Q67: 0.46260629 | R67: 1.4281698 | S67: 78.301164 | T67: 0.65578624 | U67: 1.2050629 | V67: 38.28 | W67: 43.06 | X67: 25.64 | Y67: 62.92 | Z67: 53.92 | AA67: 75.27 | AB67: 44.34 | AC67: 43.4 | AD67: 52.62
A68: Adam Smith | B68: 34 | C68: Bournemouth | D68: D(LR),M(LR) | E68: gb-eng | F68: 6.4525657 | G68: 0 | H68: 0.048901274 | I68: 0.011520721 | J68: 0.16067561 | K68: 0.57773362 | L68: 33.138297 | M68: 0.52813376 | N68: 0.81874704 | O68: 1.6151392 | P68: 0.35069199 | Q68: 0.23612329 | R68: 0.90467356 | S68: 77.79059 | T68: 0.31995405 | U68: 0.69160373 | V68: 0 | W68: 34.15 | X68: 12.11 | Y68: 33.21 | Z68: 47.04 | AA68: 48.49 | AB68: 29.59 | AC68: 17.32 | AD68: 39.31
A69: Adam Wharton | B69: 22 | C69: Crystal Palace | D69: DMC | E69: gb-eng | F69: 6.7667545 | G69: 0.036627651 | H69: 0.16775464 | I69: 0.038274724 | J69: 0.91422618 | K69: 1.457048 | L69: 46.441664 | M69: 0.70251835 | N69: 1.2402123 | O69: 2.6599 | P69: 0.193394 | Q69: 0.45564798 | R69: 0.71570431 | S69: 80.975043 | T69: 0.91788894 | U69: 1.17355 | V69: 17.96 | W69: 78.51 | X69: 20.01 | Y69: 79.5 | Z69: 87.5 | AA69: 77.42 | AB69: 44.06 | AC69: 38.28 | AD69: 27.61
...

Sheet RADAR_DATA
A1: Metric | B1: Player 1 | C1: Player 2
A2: Goals | B2: =IFERROR(XLOOKUP(DASHBOARD!$B$6,DATA!$A:$A,DATA!$V:$V,0),0) | C2: =IFERROR(XLOOKUP(DASHBOARD!$I$6,DATA!$A:$A,DATA!$V:$V,0),0)
A3: xG | B3: =IFERROR(XLOOKUP(DASHBOARD!$B$6,DATA!$A:$A,DATA!$X:$X,0),0) | C3: =IFERROR(XLOOKUP(DASHBOARD!$I$6,DATA!$A:$A,DATA!$X:$X,0),0)
A4: Key Passes | B4: =IFERROR(XLOOKUP(DASHBOARD!$B$6,DATA!$A:$A,DATA!$Y:$Y,0),0) | C4: =IFERROR(XLOOKUP(DASHBOARD!$I$6,DATA!$A:$A,DATA!$Y:$Y,0),0)
A5: Tackles | B5: =IFERROR(XLOOKUP(DASHBOARD!$B$6,DATA!$A:$A,DATA!$Z:$Z,0),0) | C5: =IFERROR(XLOOKUP(DASHBOARD!$I$6,DATA!$A:$A,DATA!$Z:$Z,0),0)
A6: Pass % | B6: =IFERROR(XLOOKUP(DASHBOARD!$B$6,DATA!$A:$A,DATA!$AB:$AB,0),0) | C6: =IFERROR(XLOOKUP(DASHBOARD!$I$6,DATA!$A:$A,DATA!$AB:$AB,0),0)
A7: Dribbles | B7: =IFERROR(XLOOKUP(DASHBOARD!$B$6,DATA!$A:$A,DATA!$AC:$AC,0),0) | C7: =IFERROR(XLOOKUP(DASHBOARD!$I$6,DATA!$A:$A,DATA!$AC:$AC,0),0)

Sheet BAR_DATA
A1: Metric | B1: Player 1 | C1: Player 2
A2: Goals/90 | B2: =IFERROR(XLOOKUP(DASHBOARD!$B$6,DATA!$A:$A,DATA!$G:$G,0),0) | C2: =IFERROR(XLOOKUP(DASHBOARD!$I$6,DATA!$A:$A,DATA!$G:$G,0),0)
A3: Assists/90 | B3: =IFERROR(XLOOKUP(DASHBOARD!$B$6,DATA!$A:$A,DATA!$H:$H,0),0) | C3: =IFERROR(XLOOKUP(DASHBOARD!$I$6,DATA!$A:$A,DATA!$H:$H,0),0)
A4: xG/90 | B4: =IFERROR(XLOOKUP(DASHBOARD!$B$6,DATA!$A:$A,DATA!$I:$I,0),0) | C4: =IFERROR(XLOOKUP(DASHBOARD!$I$6,DATA!$A:$A,DATA!$I:$I,0),0)
A5: Shots/90 | B5: =IFERROR(XLOOKUP(DASHBOARD!$B$6,DATA!$A:$A,DATA!$J:$J,0),0) | C5: =IFERROR(XLOOKUP(DASHBOARD!$I$6,DATA!$A:$A,DATA!$J:$J,0),0)
A6: Key Pass/90 | B6: =IFERROR(XLOOKUP(DASHBOARD!$B$6,DATA!$A:$A,DATA!$K:$K,0),0) | C6: =IFERROR(XLOOKUP(DASHBOARD!$I$6,DATA!$A:$A,DATA!$K:$K,0),0)
A7: Passes/90 | B7: =IFERROR(XLOOKUP(DASHBOARD!$B$6,DATA!$A:$A,DATA!$L:$L,0),0) | C7: =IFERROR(XLOOKUP(DASHBOARD!$I$6,DATA!$A:$A,DATA!$L:$L,0),0)
A8: Crosses/90 | B8: =IFERROR(XLOOKUP(DASHBOARD!$B$6,DATA!$A:$A,DATA!$M:$M,0),0) | C8: =IFERROR(XLOOKUP(DASHBOARD!$I$6,DATA!$A:$A,DATA!$M:$M,0),0)
A9: Interc./90 | B9: =IFERROR(XLOOKUP(DASHBOARD!$B$6,DATA!$A:$A,DATA!$N:$N,0),0) | C9: =IFERROR(XLOOKUP(DASHBOARD!$I$6,DATA!$A:$A,DATA!$N:$N,0),0)
A10: Tackles/90 | B10: =IFERROR(XLOOKUP(DASHBOARD!$B$6,DATA!$A:$A,DATA!$O:$O,0),0) | C10: =IFERROR(XLOOKUP(DASHBOARD!$I$6,DATA!$A:$A,DATA!$O:$O,0),0)
A11: Blocks/90 | B11: =IFERROR(XLOOKUP(DASHBOARD!$B$6,DATA!$A:$A,DATA!$P:$P,0),0) | C11: =IFERROR(XLOOKUP(DASHBOARD!$I$6,DATA!$A:$A,DATA!$P:$P,0),0)
A12: Dribbles/90 | B12: =IFERROR(XLOOKUP(DASHBOARD!$B$6,DATA!$A:$A,DATA!$Q:$Q,0),0) | C12: =IFERROR(XLOOKUP(DASHBOARD!$I$6,DATA!$A:$A,DATA!$Q:$Q,0),0)
A13: Aerials/90 | B13: =IFERROR(XLOOKUP(DASHBOARD!$B$6,DATA!$A:$A,DATA!$R:$R,0),0) | C13: =IFERROR(XLOOKUP(DASHBOARD!$I$6,DATA!$A:$A,DATA!$R:$R,0),0)
